Workbook

Sheet Léeme
A1: Lavanderías y tintorerías del territorio
A2: Todo el estado de Durango, más Torreón y Matamoros, Coahuila. Preparado por Nazmelia.
A4: Qué es este archivo
A5: La lista de los 415 negocios de lavandería y tintorería que el INEGI tiene registrados en el territorio, con su dirección, teléfono, correo y página cuando el INEGI los tiene.
A6: Sirve para buscar lavanderías socias: a quién llamar, en qué zona y cómo va cada llamada.
A8: De dónde salen los datos
A9: Del Directorio Estadístico Nacional de Unidades Económicas del INEGI, en su edición más reciente, actividad «Lavanderías y tintorerías».
A10: Es un registro público y oficial. Los datos los capturó el INEGI; nosotros solo los ordenamos y los dejamos listos para usar.
A12: Qué hay en cada hoja
A13: Resumen: cuántos negocios hay en cada plaza y cuántos tienen teléfono, correo o página. También lleva la cuenta de las llamadas.
A14: Por municipio: lo mismo, municipio por municipio.
A15: Listado: un negocio por renglón. Se puede filtrar por plaza, municipio o colonia con las flechas del encabezado.
... A29: Este archivo no mide si los negocios tienen presencia en internet ni cuántas personas buscan el servicio. Eso se trabaja aparte.

Sheet Resumen
A1: Resumen por plaza
A2: Las cifras se recalculan solas a partir de la hoja Listado.
A4: Plaza | B4: Negocios | C4: Con teléfono | D4: Con correo | E4: Con página o red social | F4: Su nombre dice lavandería | G4: Su nombre dice tintorería | H4: Su nombre dice planchaduría | I4: No se sabe por el nombre | J4: Ya se les llamó | K4: Les interesa
A5: Durango capital | B5: =COUNTIF(Listado!$B$2:$B$416,$A5) -> 152 | C5: =COUNTIFS(Listado!$B$2:$B$416,$A5,Listado!$L$2:$L$416,"<>") -> 78 | D5: =COUNTIFS(Listado!$B$2:$B$416,$A5,Listado!$M$2:$M$416,"<>") -> 14 | E5: =COUNTIFS(Listado!$B$2:$B$416,$A5,Listado!$N$2:$N$416,"<>") -> 3 | F5: =COUNTIFS(Listado!$B$2:$B$416,$A5,Listado!$G$2:$G$416,"*avandería*") -> 124 | G5: =COUNTIFS(Listado!$B$2:$B$416,$A5,Listado!$G$2:$G$416,"*intorería*") -> 12 | H5: =COUNTIFS(Listado!$B$2:$B$416,$A5,Listado!$G$2:$G$416,"*lanchaduría*") -> 33 | I5: =COUNTIFS(Listado!$B$2:$B$416,$A5,Listado!$G$2:$G$416,"No se sabe por el nombre") -> 8 | J5: =COUNTIFS(Listado!$B$2:$B$416,$A5,Listado!$S$2:$S$416,"Sí") -> 0 | K5: =COUNTIFS(Listado!$B$2:$B$416,$A5,Listado!$T$2:$T$416,"Le interesa") -> 0
A6: Gómez Palacio y Lerdo | B6: =COUNTIF(Listado!$B$2:$B$416,$A6) -> 52 | C6: =COUNTIFS(Listado!$B$2:$B$416,$A6,Listado!$L$2:$L$416,"<>") -> 27 | D6: =COUNTIFS(Listado!$B$2:$B$416,$A6,Listado!$M$2:$M$416,"<>") -> 8 | E6: =COUNTIFS(Listado!$B$2:$B$416,$A6,Listado!$N$2:$N$416,"<>") -> 1 | F6: =COUNTIFS(Listado!$B$2:$B$416,$A6,Listado!$G$2:$G$416,"*avandería*") -> 40 | G6: =COUNTIFS(Listado!$B$2:$B$416,$A6,Listado!$G$2:$G$416,"*intorería*") -> 7 | H6: =COUNTIFS(Listado!$B$2:$B$416,$A6,Listado!$G$2:$G$416,"*lanchaduría*") -> 8 | I6: =COUNTIFS(Listado!$B$2:$B$416,$A6,Listado!$G$2:$G$416,"No se sabe por el nombre") -> 3 | J6: =COUNTIFS(Listado!$B$2:$B$416,$A6,Listado!$S$2:$S$416,"Sí") -> 0 | K6: =COUNTIFS(Listado!$B$2:$B$416,$A6,Listado!$T$2:$T$416,"Le interesa") -> 0
A7: Torreón | B7: =COUNTIF(Listado!$B$2:$B$416,$A7) -> 146 | C7: =COUNTIFS(Listado!$B$2:$B$416,$A7,Listado!$L$2:$L$416,"<>") -> 81 | D7: =COUNTIFS(Listado!$B$2:$B$416,$A7,Listado!$M$2:$M$416,"<>") -> 28 | E7: =COUNTIFS(Listado!$B$2:$B$416,$A7,Listado!$N$2:$N$416,"<>") -> 7 | F7: =COUNTIFS(Listado!$B$2:$B$416,$A7,Listado!$G$2:$G$416,"*avandería*") -> 89 | G7: =COUNTIFS(Listado!$B$2:$B$416,$A7,Listado!$G$2:$G$416,"*intorería*") -> 33 | H7: =COUNTIFS(Listado!$B$2:$B$416,$A7,Listado!$G$2:$G$416,"*lanchaduría*") -> 23 | I7: =COUNTIFS(Listado!$B$2:$B$416,$A7,Listado!$G$2:$G$416,"No se sabe por el nombre") -> 18 | J7: =COUNTIFS(Listado!$B$2:$B$416,$A7,Listado!$S$2:$S$416,"Sí") -> 0 | K7: =COUNTIFS(Listado!$B$2:$B$416,$A7,Listado!$T$2:$T$416,"Le interesa") -> 0
A8: Matamoros | B8: =COUNTIF(Listado!$B$2:$B$416,$A8) -> 3 | C8: =COUNTIFS(Listado!$B$2:$B$416,$A8,Listado!$L$2:$L$416,"<>") -> 3 | D8: =COUNTIFS(Listado!$B$2:$B$416,$A8,Listado!$M$2:$M$416,"<>") -> 0 | E8: =COUNTIFS(Listado!$B$2:$B$416,$A8,Listado!$N$2:$N$416,"<>") -> 0 | F8: =COUNTIFS(Listado!$B$2:$B$416,$A8,Listado!$G$2:$G$416,"*avandería*") -> 3 | G8: =COUNTIFS(Listado!$B$2:$B$416,$A8,Listado!$G$2:$G$416,"*intorería*") -> 0 | H8: =COUNTIFS(Listado!$B$2:$B$416,$A8,Listado!$G$2:$G$416,"*lanchaduría*") -> 0 | I8: =COUNTIFS(Listado!$B$2:$B$416,$A8,Listado!$G$2:$G$416,"No se sabe por el nombre") -> 0 | J8: =COUNTIFS(Listado!$B$2:$B$416,$A8,Listado!$S$2:$S$416,"Sí") -> 0 | K8: =COUNTIFS(Listado!$B$2:$B$416,$A8,Listado!$T$2:$T$416,"Le interesa") -> 0
A9: Resto del estado de Durango | B9: =COUNTIF(Listado!$B$2:$B$416,$A9) -> 62 | C9: =COUNTIFS(Listado!$B$2:$B$416,$A9,Listado!$L$2:$L$416,"<>") -> 41 | D9: =COUNTIFS(Listado!$B$2:$B$416,$A9,Listado!$M$2:$M$416,"<>") -> 1 | E9: =COUNTIFS(Listado!$B$2:$B$416,$A9,Listado!$N$2:$N$416,"<>") -> 0 | F9: =COUNTIFS(Listado!$B$2:$B$416,$A9,Listado!$G$2:$G$416,"*avandería*") -> 61 | G9: =COUNTIFS(Listado!$B$2:$B$416,$A9,Listado!$G$2:$G$416,"*intorería*") -> 3 | H9: =COUNTIFS(Listado!$B$2:$B$416,$A9,Listado!$G$2:$G$416,"*lanchaduría*") -> 3 | I9: =COUNTIFS(Listado!$B$2:$B$416,$A9,Listado!$G$2:$G$416,"No se sabe por el nombre") -> 0 | J9: =COUNTIFS(Listado!$B$2:$B$416,$A9,Listado!$S$2:$S$416,"Sí") -> 0 | K9: =COUNTIFS(Listado!$B$2:$B$416,$A9,Listado!$T$2:$T$416,"Le interesa") -> 0
A10: Todo el territorio | B10: =SUM(B5:B9) -> 415 | C10: =SUM(C5:C9) -> 230 | D10: =SUM(D5:D9) -> 51 | E10: =SUM(E5:E9) -> 11 | F10: =SUM(F5:F9) -> 317 | G10: =SUM(G5:G9) -> 55 | H10: =SUM(H5:H9) -> 67 | I10: =SUM(I5:I9) -> 29 | ... K10: =SUM(K5:K9) -> 0
A12: Cómo leer este resumen
A13: • «Negocios» cuenta cada local por separado: si un negocio tiene tres sucursales, aparecen tres.
A14: • Las columnas «Su nombre dice…» salen solo del nombre del negocio. Un negocio puede contar en más de una (por ejemplo, «Lavandería y planchaduría»), y uno que solo dice «Lavandería» puede también planchar o lavar en seco: se confirma en la llamada.
A15: • «Ya se les llamó» y «Les interesa» se llenan solas cuando alguien marca esas columnas en la hoja Listado.

Sheet Por municipio
A1: Negocios por municipio
A2: Ordenados de mayor a menor.
A4: Plaza | B4: Municipio | C4: Negocios | D4: Con teléfono
A5: Durango capital | B5: Durango | C5: =COUNTIF(Listado!$C$2:$C$416,$B5) -> 152 | D5: =COUNTIFS(Listado!$C$2:$C$416,$B5,Listado!$L$2:$L$416,"<>") -> 78
A6: Gómez Palacio y Lerdo | B6: Gómez Palacio | C6: =COUNTIF(Listado!$C$2:$C$416,$B6) -> 41 | D6: =COUNTIFS(Listado!$C$2:$C$416,$B6,Listado!$L$2:$L$416,"<>") -> 19
A7: Gómez Palacio y Lerdo | B7: Lerdo | C7: =COUNTIF(Listado!$C$2:$C$416,$B7) -> 11 | D7: =COUNTIFS(Listado!$C$2:$C$416,$B7,Listado!$L$2:$L$416,"<>") -> 8
A8: Torreón | B8: Torreón | C8: =COUNTIF(Listado!$C$2:$C$416,$B8) -> 146 | D8: =COUNTIFS(Listado!$C$2:$C$416,$B8,Listado!$L$2:$L$416,"<>") -> 81
A9: Matamoros | B9: Matamoros | C9: =COUNTIF(Listado!$C$2:$C$416,$B9) -> 3 | D9: =COUNTIFS(Listado!$C$2:$C$416,$B9,Listado!$L$2:$L$416,"<>") -> 3
A10: Resto del estado de Durango | B10: Santiago Papasquiaro | C10: =COUNTIF(Listado!$C$2:$C$416,$B10) -> 10 | D10: =COUNTIFS(Listado!$C$2:$C$416,$B10,Listado!$L$2:$L$416,"<>") -> 7
A11: Resto del estado de Durango | B11: Guadalupe Victoria | C11: =COUNTIF(Listado!$C$2:$C$416,$B11) -> 6 | D11: =COUNTIFS(Listado!$C$2:$C$416,$B11,Listado!$L$2:$L$416,"<>") -> 3
A12: Resto del estado de Durango | B12: Canatlán | C12: =COUNTIF(Listado!$C$2:$C$416,$B12) -> 5 | D12: =COUNTIFS(Listado!$C$2:$C$416,$B12,Listado!$L$2:$L$416,"<>") -> 3
A13: Resto del estado de Durango | B13: Nuevo Ideal | C13: =COUNTIF(Listado!$C$2:$C$416,$B13) -> 5 | D13: =COUNTIFS(Listado!$C$2:$C$416,$B13,Listado!$L$2:$L$416,"<>") -> 4
A14: Resto del estado de Durango | B14: Poanas | C14: =COUNTIF(Listado!$C$2:$C$416,$B14) -> 4 | D14: =COUNTIFS(Listado!$C$2:$C$416,$B14,Listado!$L$2:$L$416,"<>") -> 3
A15: Resto del estado de Durango | B15: Cuencamé | C15: =COUNTIF(Listado!$C$2:$C$416,$B15) -> 3 | D15: =COUNTIFS(Listado!$C$2:$C$416,$B15,Listado!$L$2:$L$416,"<>") -> 1
A16: Resto del estado de Durango | B16: Pueblo Nuevo | C16: =COUNTIF(Listado!$C$2:$C$416,$B16) -> 3 | D16: =COUNTIFS(Listado!$C$2:$C$416,$B16,Listado!$L$2:$L$416,"<>") -> 2
... A31: Resto del estado de Durango | B31: Tlahualilo | C31: =COUNTIF(Listado!$C$2:$C$416,$B31) -> 1 | D31: =COUNTIFS(Listado!$C$2:$C$416,$B31,Listado!$L$2:$L$416,"<>") -> 1

Sheet Listado
A1: N.º | B1: Plaza | C1: Municipio | D1: Localidad | E1: Nombre del negocio | F1: Razón social | G1: Qué es, según su nombre | H1: Personas que trabajan ahí | I1: Calle y número | J1: Colonia | K1: Código postal | L1: Teléfono | M1: Correo | N1: Página web o red social | O1: Ver en el mapa | P1: Latitud | Q1: Longitud | R1: Clave del INEGI | S1: ¿Ya se le llamó? | T1: Resultado de la llamada | U1: Notas
A2: 1 | B2: Durango capital | C2: Durango | D2: Victoria de Durango | E2: BEE LAVANDERIA & PLANCHADO | G2: Lavandería y planchaduría | H2: 0 a 5 personas | I2: Avenida Nuevo Durango 440 | J2: Fraccionamiento Nuevo Durango I | K2: 34166 | O2: Abrir mapa | P2: 24.003157 | Q2: -104.63794 | R2: 10356245
A3: 2 | B3: Durango capital | C3: Durango | D3: Victoria de Durango | E3: CENTRO DE LAVADO Y SECADO DE ROPA | G3: Lavandería | H3: 0 a 5 personas | I3: Avenida Division Durango 800 | J3: Fraccionamiento Domingo Arrieta | K3: 34180 | O3: Abrir mapa | P3: 23.996394 | Q3: -104.66902 | R3: 1083064
A4: 3 | B4: Durango capital | C4: Durango | D4: Victoria de Durango | E4: CENTRO DE LAVANDERIA Y PLACHADURIA | G4: Lavandería | H4: 0 a 5 personas | I4: Avenida Cuauhtemoc 608 | J4: Fraccionamiento Huizache I | K4: 34160 | L4: 618 131 6733 | O4: Abrir mapa | P4: 24.006771 | Q4: -104.65478 | R4: 10089801
A5: 4 | B5: Durango capital | C5: Durango | D5: Victoria de Durango | E5: CICLOS PLANCHADO | G5: Planchaduría | H5: 0 a 5 personas | I5: Calle 5 De Febrero 1502 A | J5: Colonia Burócrata | K5: 34279 | L5: 552 726 7858 | M5: barrazamontse966@gmail.com | O5: Abrir mapa | P5: 24.026447 | Q5: -104.64929 | R5: 8605159
A6: 5 | B6: Durango capital | C6: Durango | D6: Victoria de Durango | E6: CLEAN FASHION | G6: No se sabe por el nombre | H6: 0 a 5 personas | I6: Prolongacion Nazas sin número | J6: Fraccionamiento Nuevo Durango I | K6: 34166 | O6: Abrir mapa | P6: 24.000495 | Q6: -104.64061 | R6: 1117866
A7: 6 | B7: Durango capital | C7: Durango | D7: Victoria de Durango | E7: ECOCLEAN | G7: No se sabe por el nombre | H7: 0 a 5 personas | I7: Calle Año De Juarez 211 | J7: Fraccionamiento Guadalupe Victoria Infonavit | K7: 34220 | O7: Abrir mapa | P7: 24.046893 | Q7: -104.61905 | R7: 10485449
A8: 7 | B8: Durango capital | C8: Durango | D8: Victoria de Durango | E8: ESTRELLAS DE LA LIMPIEZA | F8: Q R LAS ESTRELLAS DE LA LIMPIEZA | G8: No se sabe por el nombre | H8: 0 a 5 personas | I8: Corredor Felipe Pescador 25 | J8: Colonia Del Maestro | K8: 34240 | O8: Abrir mapa | P8: 24.033498 | Q8: -104.63972 | R8: 11116366
A9: 8 | B9: Durango capital | C9: Durango | D9: Victoria de Durango | E9: EVERCLEAN LAVANDERIA | G9: Lavandería | H9: 0 a 5 personas | I9: Avenida Sahuatoba 216, Plaza Lomas | J9: Fraccionamiento Lomas Del Parque | K9: 34108 | M9: cmme65@prodigy.net.mx | O9: Abrir mapa | P9: 24.014328 | Q9: -104.69055 | R9: 7258753
A10: 9 | B10: Durango capital | C10: Durango | D10: Cinco de Mayo | E10: FRESH CLEAN LAVANDERIA | G10: Lavandería | H10: 0 a 5 personas | I10: Prolongacion Francisco Villa 208 | J10: Pueblo 5 De Mayo | K10: 34304 | O10: Abrir mapa | P10: 24.098655 | Q10: -104.57597 | R10: 11829493
A11: 10 | B11: Durango capital | C11: Durango | D11: Victoria de Durango | E11: KLIN LAVANDERIA | G11: Lavandería | H11: 0 a 5 personas | I11: Boulevard Instituto Politecnico Nacional sin número | J11: Fraccionamiento Camino Real | K11: 34170 | L11: 618 310 2020 | N11: www.klino.mx | O11: Abrir mapa | P11: 24.006144 | Q11: -104.65742 | R11: 8519619
A12: 11 | B12: Durango capital | C12: Durango | D12: Victoria de Durango | E12: KLINO LAVANDERIAS | G12: Lavandería | H12: 0 a 5 personas | I12: Boulevard De La Juventud sin número | J12: Colonia Luis Echeverría | K12: 34250 | L12: 618 310 2020 | N12: www.klino.mx | O12: Abrir mapa | P12: 24.031392 | Q12: -104.62425 | R12: 9775134
A13: 12 | B13: Durango capital | C13: Durango | D13: Victoria de Durango | E13: KLINO LAVANDERIAS | G13: Lavandería | H13: 0 a 5 personas | I13: Boulevard Durango sin número | J13: Colonia Sarh | K13: 34180 | M13: klinolavanderias@gmail.com | N13: www.klino.mx | O13: Abrir mapa | P13: 24.010447 | Q13: -104.69065 | R13: 7258747
A14: 13 | B14: Durango capital | C14: Durango | D14: Victoria de Durango | E14: LAVA FACIL LAVANDERIA | G14: Lavandería | H14: 0 a 5 personas | I14: Circuito Palenque 308 | J14: Fraccionamiento Huizache I | K14: 34160 | L14: 618 231 9152 | O14: Abrir mapa | P14: 24.010605 | Q14: -104.65351 | R14: 1094784
A15: 14 | B15: Durango capital | C15: Durango | D15: Victoria de Durango | E15: LAVA NUBES | G15: Lavandería | H15: 0 a 5 personas | I15: Avenida Resplandor 200 C | J15: Fraccionamiento Las Nubes | K15: 34224 | L15: 618 819 2093 | O15: Abrir mapa | P15: 24.054751 | Q15: -104.59532 | R15: 7265074
A16: 15 | B16: Durango capital | C16: Durango | D16: Victoria de Durango | E16: LAVA PLANCH | G16: Lavandería y planchaduría | H16: 0 a 5 personas | I16: Circuito Chamula 734 B | J16: Fraccionamiento Huizache I | K16: 34160 | L16: 618 211 4235 | O16: Abrir mapa | P16: 24.005459 | Q16: -104.65517 | R16: 7404294
A17: 16 | B17: Durango capital | C17: Durango | D17: Victoria de Durango | E17: LAVADO Y PLANCHADO REAL | G17: Lavandería y planchaduría | H17: 0 a 5 personas | I17: Calle Guadalajara 633, interior 2 | J17: Fraccionamiento Jalisco | K17: 34170 | O17: Abrir mapa | P17: 24.002517 | Q17: -104.65352 | R17: 1113993
A18: 17 | B18: Durango capital | C18: Durango | D18: Victoria de Durango | E18: LAVAMATIC | G18: Lavandería | H18: 0 a 5 personas | I18: Calle Constituyentes 705 | J18: Fraccionamiento Las Fuentes | K18: 34220 | O18: Abrir mapa | P18: 24.045001 | Q18: -104.61953 | R18: 1083549
A19: 18 | B19: Durango capital | C19: Durango | D19: Victoria de Durango | E19: LAVANDERIA | F19: LAVANDERIA | G19: Lavandería | H19: 0 a 5 personas | I19: Calle Camino De Los Castillos 252 | J19: Fraccionamiento Paso Real | K19: 34204 | O19: Abrir mapa | P19: 24.058404 | Q19: -104.61962 | R19: 11116777
A20: 19 | B20: Durango capital | C20: Durango | D20: Victoria de Durango | E20: LAVANDERIA | G20: Lavandería | H20: 0 a 5 personas | I20: Calle Carlos Santamaria sin número | J20: Colonia Héctor Mayagoitia Domínguez | K20: 34010 | O20: Abrir mapa | P20: 24.044177 | Q20: -104.68958 | R20: 10083846
A21: 20 | B21: Durango capital | C21: Durango | D21: Victoria de Durango | E21: LAVANDERIA ALEXJOS | G21: Lavandería | H21: 0 a 5 personas | I21: Boulevard Jose Maria Patoni 406 | J21: Colonia José Revueltas | K21: 34219 | L21: 618 230 9042 | O21: Abrir mapa | P21: 24.049305 | Q21: -104.64846 | R21: 7424397
A22: 21 | B22: Durango capital | C22: Durango | D22: Victoria de Durango | E22: LAVANDERIA ALICIA | G22: Lavandería | H22: 0 a 5 personas | I22: Avenida Coronel Enrique Carrola Antuna 1203 B | J22: Colonia J. Guadalupe Rodríguez | K22: 34280 | L22: 618 257 8082 | O22: Abrir mapa | P22: 24.020972 | Q22: -104.62715 | R22: 7319356
A23: 22 | B23: Durango capital | C23: Durango | D23: Victoria de Durango | E23: LAVANDERIA AMERICA | G23: Lavandería | H23: 0 a 5 personas | I23: Boulevard Licenciado Armando Del Castillo Franco 136 | J23: Fraccionamiento Lomas Del Parque | K23: 34100 | O23: Abrir mapa | P23: 24.017992 | Q23: -104.69021 | R23: 1082692
A24: 23 | B24: Durango capital | C24: Durango | D24: Victoria de Durango | E24: LAVANDERIA ANGY | G24: Lavandería | H24: 0 a 5 personas | I24: Calle Del Guadiana sin número | J24: Fraccionamiento Valle Oriente | K24: 34224 | O24: Abrir mapa | P24: 24.056845 | Q24: -104.58707 | R24: 11165699
A25: 24 | B25: Durango capital | C25: Durango | D25: Victoria de Durango | E25: LAVANDERIA ARCOIRIS | G25: Lavandería | H25: 0 a 5 personas | I25: Boulevard Domingo Arrieta 511 C | J25: Colonia Juan Lira Bracho | K25: 34188 | L25: 618 256 0481 | M25: erendy_86@hotmail.com | O25: Abrir mapa | P25: 23.9874 | Q25: -104.66451 | R25: 9878860
A26: 25 | B26: Durango capital | C26: Durango | D26: Victoria de Durango | E26: LAVANDERIA AUTOMATICA ALE | G26: Lavandería | H26: 0 a 5 personas | I26: Avenida General Lazaro Cardenas 232 | J26: Colonia Real Del Prado | K26: 34080 | O26: Abrir mapa | P26: 24.032086 | Q26: -104.65354 | R26: 1080707
A27: 26 | B27: Durango capital | C27: Durango | D27: Victoria de Durango | E27: LAVANDERIA BIEN LIMPIO | G27: Lavandería | H27: 0 a 5 personas | I27: Avenida Rio De Janeiro 544 A | J27: Fraccionamiento Guadalupe | K27: 34220 | M27: mmgrios@hotmail.com | O27: Abrir mapa | P27: 24.043514 | Q27: -104.62224 | R27: 7811767
A28: 27 | B28: Durango capital | C28: Durango | D28: Victoria de Durango | E28: LAVANDERIA BLUEWASH | G28: Lavandería | H28: 0 a 5 personas | I28: Prolongacion Nazas sin número, interior 6 | J28: Fraccionamiento Santa Teresa | K28: 34166 | O28: Abrir mapa | P28: 24.005488 | Q28: -104.64406 | R28: 7830287
A29: 28 | B29: Durango capital | C29: Durango | D29: Victoria de Durango | E29: LAVANDERIA CLEAN CENTER | G29: Lavandería | H29: 0 a 5 personas | I29: Calle Hernandez 1525 | J29: Colonia Zona Centro | K29: 34000 | O29: Abrir mapa | P29: 24.032549 | Q29: -104.67903 | R29: 9379618
A30: 29 | B30: Durango capital | C30: Durango | D30: Victoria de Durango | E30: LAVANDERIA COLOR MAGIC | F30: GLORIA | G30: Lavandería | H30: 0 a 5 personas | I30: Calle Orion 1002 | J30: Fraccionamiento Villas Del Guadiana Iii | K30: 34224 | L30: 618 292 7930 | O30: Abrir mapa | P30: 24.070035 | Q30: -104.58934 | R30: 11458379
A31: 30 | B31: Durango capital | C31: Durango | D31: Victoria de Durango | E31: LAVANDERIA DEL RIO | G31: Lavandería | H31: 0 a 5 personas | I31: Avenida Coronel Enrique Carrola Antuna sin número | J31: Colonia Canela | K31: 34270 | O31: Abrir mapa | P31: 24.020047 | Q31: -104.64114 | R31: 10131945
A32: 31 | B32: Durango capital | C32: Durango | D32: Victoria de Durango | E32: LAVANDERIA DERECK | G32: Lavandería | H32: 0 a 5 personas | I32: Calle Del Atardecer 132 | J32: Fraccionamiento La Luz | K32: 34225 | L32: 677 119 8584 | O32: Abrir mapa | P32: 24.058303 | Q32: -104.58783 | R32: 7264755
A33: 32 | B33: Durango capital | C33: Durango | D33: Victoria de Durango | E33: LAVANDERIA EL NOGAL | G33: Lavandería | H33: 0 a 5 personas | I33: Calle Francisco Gonzalez De La Vega 105 | J33: Colonia Iv Centenario | K33: 34150 | L33: 618 366 2704 | O33: Abrir mapa | P33: 24.010338 | Q33: -104.66982 | R33: 11723284
A34: 33 | B34: Durango capital | C34: Durango | D34: Victoria de Durango | E34: LAVANDERIA EL TENDERO | G34: Lavandería | H34: 0 a 5 personas | I34: Calle 50 Aniversario Itd 129 B | J34: Fraccionamiento Aserradero | K34: 34214 | M34: eltendedederolavanderia.dgo@gmail.com | O34: Abrir mapa | P34: 24.041285 | Q34: -104.64969 | R34: 7424420
A35: 34 | B35: Durango capital | C35: Durango | D35: Victoria de Durango | E35: LAVANDERIA ESPUMITA | G35: Lavandería | H35: 0 a 5 personas | I35: Boulevard Juan Pablo Ii 223 | J35: Fraccionamiento Jardines De Durango | K35: 34200 | O35: Abrir mapa | P35: 24.04405 | Q35: -104.63569 | R35: 9000005
A36: 35 | B36: Durango capital | C36: Durango | D36: Victoria de Durango | E36: LAVANDERIA ESTRELLAS DE LA LIMPIEZA | G36: Lavandería | H36: 0 a 5 personas | I36: Boulevard Juan Pablo Ii 125 | J36: Fraccionamiento Jardines De Durango | K36: 34200 | O36: Abrir mapa | P36: 24.044756 | Q36: -104.63644 | R36: 9566210
A37: 36 | B37: Durango capital | C37: Durango | D37: Victoria de Durango | E37: LAVANDERIA EVELYN | G37: Lavandería | H37: 0 a 5 personas | I37: Calle Murallas 115 | J37: Colonia Villa De Guadalupe | K37: 34040 | O37: Abrir mapa | P37: 24.042375 | Q37: -104.68424 | R37: 9360530
A38: 37 | B38: Durango capital | C38: Durango | D38: Victoria de Durango | E38: LAVANDERIA EXPRESS | G38: Lavandería | H38: 0 a 5 personas | I38: Avenida La Salle 502 B | J38: Residencial Colinas Del Saltito | K38: 34105 | O38: Abrir mapa | P38: 24.009723 | Q38: -104.71069 | R38: 7259455
A39: 38 | B39: Durango capital | C39: Durango | D39: Victoria de Durango | E39: LAVANDERIA EXPRESS | G39: Lavandería | H39: 0 a 5 personas | I39: Prolongacion 20 De Noviembre 408 | J39: Fraccionamiento Los Duraznos | K39: 34238 | O39: Abrir mapa | P39: 24.040961 | Q39: -104.59922 | R39: 1092524
A40: 39 | B40: Durango capital | C40: Durango | D40: Victoria de Durango | E40: LAVANDERIA EXPRESS | G40: Lavandería | H40: 0 a 5 personas | I40: Boulevard Hermila Galindo Acosta sin número | J40: Residencial Los Pinos | K40: 34162 | O40: Abrir mapa | P40: 23.997986 | Q40: -104.64249 | R40: 9354995
...

Sheet Otras posibles
A1: Otros negocios que podrían lavar ropa
A2: El INEGI los registró con otra actividad, pero su nombre dice lavandería o tintorería. No están en el Listado ni en el Resumen.
A4: Municipio | B4: Nombre del negocio | C4: Actividad registrada | D4: Calle y número | E4: Colonia | F4: Teléfono | G4: Clave del INEGI
A5: Durango | B5: LAVANDERIA Y CIBER VICTORIA | C5: Servicios de acceso a computadoras | D5: Calle Cetus 112 | E5: Fraccionamiento Villas Del Guadiana Ii | G5: 9032034
A6: Gómez Palacio | B6: INDUSTRIAS APPAREL LAVANDERIA | C6: Confección en serie de otra ropa exterior de materiales textiles | D6: Calle Guanaceví 207 | E6: Parque Industrial Carlos Herrera Araluce | G6: 6866367
A7: Gómez Palacio | B7: LAVANDERIA HG | C7: Confección en serie de otra ropa exterior de materiales textiles | D7: Avenida Primavera 2042 | E7: Colonia Miguel De La Madrid | F7: 871 333 0008 | G7: 10496627
A8: Tepehuanes | B8: LAVANDERIA Y AUTOLAVADO EBEN EZER | C8: Lavado y lubricado de automóviles y camiones | D8: Calle Palma 209 | E8: Colonia Centro | F8: 674 111 3613 | G8: 1074902
