Workbook
Name Print_Titles: 'Para llamar'!$1:$1
Name Print_Titles: 'Para visitar'!$1:$1

Sheet Resumen
A1: Lavanderías para invitar a Lavandi
A2: Estado de Durango, Torreón y Matamoros · Preparado por Nazmelia
A4: =COUNTA('Para llamar'!$A$2:$A$231)+COUNTA('Para visitar'!$A$2:$A$186) -> 415 | C4: =COUNTA('Para llamar'!$A$2:$A$231) -> 230 | E4: 7 de cada 10
A5: lavanderías en la zona | C5: con teléfono, listas para llamar | E5: están en Durango capital y Torreón
A7: Por zona
A8: Zona | B8: Lavanderías | C8: Para llamar | D8: Contactadas | E8: Interesadas
A9: Durango capital | B9: =COUNTIF('Para llamar'!$A$2:$A$231,$A9)+COUNTIF('Para visitar'!$A$2:$A$186,$A9) -> 152 | C9: =COUNTIF('Para llamar'!$A$2:$A$231,$A9) -> 78 | D9: =COUNTIFS('Para llamar'!$A$2:$A$231,$A9,'Para llamar'!$H$2:$H$231,"Sí")+COUNTIFS('Para visitar'!$A$2:$A$186,$A9,'Para visitar'!$G$2:$G$186,"Sí") -> 0 | E9: =COUNTIFS('Para llamar'!$A$2:$A$231,$A9,'Para llamar'!$I$2:$I$231,"Le interesa")+COUNTIFS('Para visitar'!$A$2:$A$186,$A9,'Para visitar'!$H$2:$H$186,"Le interesa") -> 0
A10: Gómez Palacio y Lerdo | B10: =COUNTIF('Para llamar'!$A$2:$A$231,$A10)+COUNTIF('Para visitar'!$A$2:$A$186,$A10) -> 52 | C10: =COUNTIF('Para llamar'!$A$2:$A$231,$A10) -> 27 | D10: =COUNTIFS('Para llamar'!$A$2:$A$231,$A10,'Para llamar'!$H$2:$H$231,"Sí")+COUNTIFS('Para visitar'!$A$2:$A$186,$A10,'Para visitar'!$G$2:$G$186,"Sí") -> 0 | E10: =COUNTIFS('Para llamar'!$A$2:$A$231,$A10,'Para llamar'!$I$2:$I$231,"Le interesa")+COUNTIFS('Para visitar'!$A$2:$A$186,$A10,'Para visitar'!$H$2:$H$186,"Le interesa") -> 0
A11: Torreón | B11: =COUNTIF('Para llamar'!$A$2:$A$231,$A11)+COUNTIF('Para visitar'!$A$2:$A$186,$A11) -> 146 | C11: =COUNTIF('Para llamar'!$A$2:$A$231,$A11) -> 81 | D11: =COUNTIFS('Para llamar'!$A$2:$A$231,$A11,'Para llamar'!$H$2:$H$231,"Sí")+COUNTIFS('Para visitar'!$A$2:$A$186,$A11,'Para visitar'!$G$2:$G$186,"Sí") -> 0 | E11: =COUNTIFS('Para llamar'!$A$2:$A$231,$A11,'Para llamar'!$I$2:$I$231,"Le interesa")+COUNTIFS('Para visitar'!$A$2:$A$186,$A11,'Para visitar'!$H$2:$H$186,"Le interesa") -> 0
A12: Matamoros | B12: =COUNTIF('Para llamar'!$A$2:$A$231,$A12)+COUNTIF('Para visitar'!$A$2:$A$186,$A12) -> 3 | C12: =COUNTIF('Para llamar'!$A$2:$A$231,$A12) -> 3 | D12: =COUNTIFS('Para llamar'!$A$2:$A$231,$A12,'Para llamar'!$H$2:$H$231,"Sí")+COUNTIFS('Para visitar'!$A$2:$A$186,$A12,'Para visitar'!$G$2:$G$186,"Sí") -> 0 | E12: =COUNTIFS('Para llamar'!$A$2:$A$231,$A12,'Para llamar'!$I$2:$I$231,"Le interesa")+COUNTIFS('Para visitar'!$A$2:$A$186,$A12,'Para visitar'!$H$2:$H$186,"Le interesa") -> 0
A13: Resto del estado de Durango | B13: =COUNTIF('Para llamar'!$A$2:$A$231,$A13)+COUNTIF('Para visitar'!$A$2:$A$186,$A13) -> 62 | C13: =COUNTIF('Para llamar'!$A$2:$A$231,$A13) -> 41 | D13: =COUNTIFS('Para llamar'!$A$2:$A$231,$A13,'Para llamar'!$H$2:$H$231,"Sí")+COUNTIFS('Para visitar'!$A$2:$A$186,$A13,'Para visitar'!$G$2:$G$186,"Sí") -> 0 | E13: =COUNTIFS('Para llamar'!$A$2:$A$231,$A13,'Para llamar'!$I$2:$I$231,"Le interesa")+COUNTIFS('Para visitar'!$A$2:$A$186,$A13,'Para visitar'!$H$2:$H$186,"Le interesa") -> 0
A14: Total | B14: =SUM(B9:B13) -> 415 | C14: =SUM(C9:C13) -> 230 | D14: =SUM(D9:D13) -> 0 | E14: =SUM(E9:E13) -> 0
A16: Cómo usarlo
A17: 1. Empiece por la hoja «Para llamar»: cada renglón es una lavandería con su teléfono.
A18: 2. Después de cada llamada, llene las tres columnas amarillas: si ya se le contactó, el resultado y una nota.
A19: 3. La hoja «Para visitar» trae las que no tienen teléfono: con «Ver mapa» se llega a la puerta.
A20: 4. Este resumen se actualiza solo con lo que se anote.
A22: Datos tomados del registro oficial de negocios del INEGI. Algún teléfono o dirección puede haber cambiado.

Sheet Para llamar
A1: Zona | B1: Municipio | C1: Lavandería | D1: Teléfono | E1: Dirección | F1: Correo o página | G1: Ubicación | H1: ¿Ya se le contactó? | I1: Resultado | J1: Notas
A2: Durango capital | B2: Durango | C2: Centro de Lavandería y Planchaduría | D2: 618 131 6733 | E2: Avenida Cuauhtemoc 608, Fraccionamiento Huizache I | G2: Ver mapa
A3: Durango capital | B3: Durango | C3: Ciclos Planchado | D3: 552 726 7858 | E3: Calle 5 de Febrero 1502 a, Colonia Burócrata | F3: barrazamontse966@gmail.com | G3: Ver mapa
A4: Durango capital | B4: Durango | C4: Klin Lavandería | D4: 618 310 2020 | E4: Boulevard Instituto Politecnico Nacional Sin Número, Fraccionamiento Camino Real | F4: www.klino.mx | G4: Ver mapa
A5: Durango capital | B5: Durango | C5: Klino Lavanderías | D5: 618 310 2020 | E5: Boulevard de la Juventud Sin Número, Colonia Luis Echeverría | F5: www.klino.mx | G5: Ver mapa
A6: Durango capital | B6: Durango | C6: Lava Facil Lavandería | D6: 618 231 9152 | E6: Circuito Palenque 308, Fraccionamiento Huizache I | G6: Ver mapa
A7: Durango capital | B7: Durango | C7: Lava Nubes | D7: 618 819 2093 | E7: Avenida Resplandor 200 C, Fraccionamiento las Nubes | G7: Ver mapa
A8: Durango capital | B8: Durango | C8: Lava Planch | D8: 618 211 4235 | E8: Circuito Chamula 734 B, Fraccionamiento Huizache I | G8: Ver mapa
A9: Durango capital | B9: Durango | C9: Lavandería Alexjos | D9: 618 230 9042 | E9: Boulevard Jose Maria Patoni 406, Colonia José Revueltas | G9: Ver mapa
A10: Durango capital | B10: Durango | C10: Lavandería Alicia | D10: 618 257 8082 | E10: Avenida Coronel Enrique Carrola Antuna 1203 B, Colonia J. Guadalupe Rodríguez | G10: Ver mapa
A11: Durango capital | B11: Durango | C11: Lavandería Arcoiris | D11: 618 256 0481 | E11: Boulevard Domingo Arrieta 511 C, Colonia Juan Lira Bracho | F11: erendy_86@hotmail.com | G11: Ver mapa
A12: Durango capital | B12: Durango | C12: Lavandería Color Magic | D12: 618 292 7930 | E12: Calle Orion 1002, Fraccionamiento Villas del Guadiana III | G12: Ver mapa
A13: Durango capital | B13: Durango | C13: Lavandería Dereck | D13: 677 119 8584 | E13: Calle del Atardecer 132, Fraccionamiento la Luz | G13: Ver mapa
A14: Durango capital | B14: Durango | C14: Lavandería el Nogal | D14: 618 366 2704 | E14: Calle Francisco Gonzalez de la Vega 105, Colonia IV Centenario | G14: Ver mapa
A15: Durango capital | B15: Durango | C15: Lavandería Grecia | D15: 618 815 8320 | E15: Calle Capricornio 316 a, Fraccionamiento Villas del Guadiana | G15: Ver mapa
A16: Durango capital | B16: Durango | C16: Lavandería GYYS | D16: 618 154 4243 | E16: Boulevard de la Juventud 711, Colonia Santa Fe | G16: Ver mapa
A17: Durango capital | B17: Durango | C17: Lavandería Independencia | D17: 618 132 2297 | E17: Calle Independencia 438, Colonia Zona Centro | G17: Ver mapa
A18: Durango capital | B18: Durango | C18: Lavandería Jessy | D18: 664 302 1715 | E18: Calle Santiago Papasquiaro Sin Número, Colonia Hipódromo | G18: Ver mapa
A19: Durango capital | B19: Durango | C19: Lavandería la Burbuja | D19: 618 196 8435 | E19: Calle Circuito Interior Sin Número, Fraccionamiento Residencial Santa Teresa | G19: Ver mapa
A20: Durango capital | B20: Durango | C20: Lavandería la Burbuja Azul | D20: 618 359 1004 | E20: Calle Domingo Arrieta 403 B, Colonia Azteca | G20: Ver mapa
A21: Durango capital | B21: Durango | C21: Lavandería la Casa del Lavado | D21: 618 188 3843 | E21: Calle Joaquín García Pascoe 100, Fraccionamiento los Agaves | G21: Ver mapa
A22: Durango capital | B22: Durango | C22: Lavandería la Casita | D22: 618 364 3946 | E22: Avenida Constelaciones 208, Fraccionamiento Nuevo Valle | G22: Ver mapa
A23: Durango capital | B23: Durango | C23: Lavandería la Casita Express | D23: 618 320 2693 | E23: Avenida Cima 335, Fraccionamiento Fstse | G23: Ver mapa
... A32: Durango capital | B32: Durango | C32: Lavandería Lavafacil | D32: 618 183 6722 | E32: Calle Colima 900 D, Colonia Valle del Guadiana | G32: Ver mapa
A33: Durango capital | B33: Durango | C33: Lavandería Lavamass | D33: 618 145 1494 | E33: Avenida Plan de Agua Prieta Sin Número, Colonia Emiliano Zapata | F33: gabytavh@hotmail.com | G33: Ver mapa
A34: Durango capital | B34: Durango | C34: Lavandería Lavampac | D34: 618 361 9245 | E34: Avenida Fidel Velazquez Sanchez 226, Fraccionamiento Fidel Velázquez | G34: Ver mapa
A35: Durango capital | B35: Durango | C35: Lavandería Limpio y Seco | D35: 618 333 0676 | E35: Calle Predio de las Peñas Sin Número, Fraccionamiento Villas de San Francisco | G35: Ver mapa
A36: Durango capital | B36: Durango | C36: Lavandería Limpizimo | D36: 618 100 7805 | E36: Prolongacion Nazas 806 e, Colonia los Sauces | F36: jarib15@hotmail.com | G36: Ver mapa
A37: Durango capital | B37: Durango | C37: Lavandería los Remedios | D37: 618 144 4101 | E37: Avenida los Remedios 609, Fraccionamiento los Remedios | G37: Ver mapa
A38: Durango capital | B38: Durango | C38: Lavandería Luca | D38: 618 273 6439 | E38: Boulevard Vialidad Mazada 113, Interior 11, Fraccionamiento Privadas del Guadiana | G38: Ver mapa
A39: Durango capital | B39: Durango | C39: Lavandería Mi Esperanza | D39: 618 309 1006 | E39: Calle Chapultepec 103, Fraccionamiento Benito Juárez | G39: Ver mapa
A40: Durango capital | B40: Durango | C40: Lavandería Miss Clean | D40: 618 304 8904 | E40: Calle Ana Leyva 216, Residencias las Torres, Colonia Nueva Vizcaya | F40: zoeluna7275@gmail.com | G40: Ver mapa
A41: Durango capital | B41: Durango | C41: Lavandería Moderna | D41: 618 187 0030 | E41: Avenida General Lazaro Cardenas 424 Sur, Colonia Zona Centro | F41: lavanderia.moderna.1950@gmail.com | G41: Ver mapa
A42: Durango capital | B42: Durango | C42: Lavandería Nena | D42: 618 235 7743 | E42: Calle Fresno Sin Número, Colonia Santa María | G42: Ver mapa
A43: Durango capital | B43: Durango | C43: Lavandería PH | D43: 618 448 1257 | E43: Calle Profesor Guadalupe G de Rodriguez 207 a, Colonia Ciénega | G43: Ver mapa
A44: Durango capital | B44: Durango | C44: Lavandería Planchaduría y Tintorería la Vale | D44: 618 823 8581 | E44: Avenida Cuitlahuac 452, Fraccionamiento el Edén | G44: Ver mapa
A45: Durango capital | B45: Durango | C45: Lavandería Roma | D45: 618 181 9094 | E45: Calle Lisboa 829 a, Fraccionamiento Roma | G45: Ver mapa
A46: Durango capital | B46: Durango | C46: Lavandería San Jose | D46: 618 132 6123 | E46: Calle Zarco Sin Número, Colonia Zona Centro | G46: Ver mapa
A47: Durango capital | B47: Durango | C47: Lavandería Secado Al Sol | D47: 618 326 5785 | E47: Calle Salubridad 410, Colonia Olga Margarita | G47: Ver mapa
A48: Durango capital | B48: Durango | C48: Lavandería Sin Nombre | D48: 618 294 1542 | E48: Calle Ricardo Flores Magon Sin Número, Colonia J. Guadalupe Rodríguez | G48: Ver mapa
...

Sheet Para visitar
A1: Zona | B1: Municipio | C1: Lavandería | D1: Dirección | E1: Correo o página | F1: Ubicación | G1: ¿Ya se le contactó? | H1: Resultado | I1: Notas
A2: Durango capital | B2: Durango | C2: Bee Lavandería & Planchado | D2: Avenida Nuevo Durango 440, Fraccionamiento Nuevo Durango I | F2: Ver mapa
A3: Durango capital | B3: Durango | C3: Centro de Lavado y Secado de Ropa | D3: Avenida Division Durango 800, Fraccionamiento Domingo Arrieta | F3: Ver mapa
A4: Durango capital | B4: Durango | C4: Clean Fashion | D4: Prolongacion Nazas Sin Número, Fraccionamiento Nuevo Durango I | F4: Ver mapa
A5: Durango capital | B5: Durango | C5: Ecoclean | D5: Calle Año de Juarez 211, Fraccionamiento Guadalupe Victoria Infonavit | F5: Ver mapa
A6: Durango capital | B6: Durango | C6: Estrellas de la Limpieza | D6: Corredor Felipe Pescador 25, Colonia del Maestro | F6: Ver mapa
A7: Durango capital | B7: Durango | C7: Everclean Lavandería | D7: Avenida Sahuatoba 216, Plaza Lomas, Fraccionamiento Lomas del Parque | E7: cmme65@prodigy.net.mx | F7: Ver mapa
A8: Durango capital | B8: Durango | C8: Fresh Clean Lavandería | D8: Prolongacion Francisco Villa 208, Pueblo 5 de Mayo | F8: Ver mapa
A9: Durango capital | B9: Durango | C9: Klino Lavanderías | D9: Boulevard Durango Sin Número, Colonia Sarh | E9: klinolavanderias@gmail.com | F9: Ver mapa
A10: Durango capital | B10: Durango | C10: Lavado y Planchado Real | D10: Calle Guadalajara 633, Interior 2, Fraccionamiento Jalisco | F10: Ver mapa
A11: Durango capital | B11: Durango | C11: Lavamatic | D11: Calle Constituyentes 705, Fraccionamiento las Fuentes | F11: Ver mapa
A12: Durango capital | B12: Durango | C12: Lavandería | D12: Calle Camino de los Castillos 252, Fraccionamiento Paso Real | F12: Ver mapa
A13: Durango capital | B13: Durango | C13: Lavandería | D13: Calle Carlos Santamaria Sin Número, Colonia Héctor Mayagoitia Domínguez | F13: Ver mapa
A14: Durango capital | B14: Durango | C14: Lavandería America | D14: Boulevard Licenciado Armando del Castillo Franco 136, Fraccionamiento Lomas del Parque | F14: Ver mapa
A15: Durango capital | B15: Durango | C15: Lavandería Angy | D15: Calle del Guadiana Sin Número, Fraccionamiento Valle Oriente | F15: Ver mapa
A16: Durango capital | B16: Durango | C16: Lavandería Automatica Ale | D16: Avenida General Lazaro Cardenas 232, Colonia Real del Prado | F16: Ver mapa
A17: Durango capital | B17: Durango | C17: Lavandería Bien Limpio | D17: Avenida Rio de Janeiro 544 a, Fraccionamiento Guadalupe | E17: mmgrios@hotmail.com | F17: Ver mapa
A18: Durango capital | B18: Durango | C18: Lavandería Bluewash | D18: Prolongacion Nazas Sin Número, Interior 6, Fraccionamiento Santa Teresa | F18: Ver mapa
A19: Durango capital | B19: Durango | C19: Lavandería Clean Center | D19: Calle Hernandez 1525, Colonia Zona Centro | F19: Ver mapa
A20: Durango capital | B20: Durango | C20: Lavandería del Rio | D20: Avenida Coronel Enrique Carrola Antuna Sin Número, Colonia Canela | F20: Ver mapa
A21: Durango capital | B21: Durango | C21: Lavandería el Tendero | D21: Calle 50 Aniversario Itd 129 B, Fraccionamiento Aserradero | E21: eltendedederolavanderia.dgo@gmail.com | F21: Ver mapa
A22: Durango capital | B22: Durango | C22: Lavandería Espumita | D22: Boulevard Juan Pablo II 223, Fraccionamiento Jardines de Durango | F22: Ver mapa
A23: Durango capital | B23: Durango | C23: Lavandería Estrellas de la Limpieza | D23: Boulevard Juan Pablo II 125, Fraccionamiento Jardines de Durango | F23: Ver mapa
A24: Durango capital | B24: Durango | C24: Lavandería Evelyn | D24: Calle Murallas 115, Colonia Villa de Guadalupe | F24: Ver mapa
A25: Durango capital | B25: Durango | C25: Lavandería Express | D25: Avenida la Salle 502 B, Residencial Colinas del Saltito | F25: Ver mapa
A26: Durango capital | B26: Durango | C26: Lavandería Express | D26: Prolongacion 20 de Noviembre 408, Fraccionamiento los Duraznos | F26: Ver mapa
A27: Durango capital | B27: Durango | C27: Lavandería Express | D27: Boulevard Hermila Galindo Acosta Sin Número, Residencial los Pinos | F27: Ver mapa
A28: Durango capital | B28: Durango | C28: Lavandería Express | D28: Calle Zacatecas 206, Colonia Morga | F28: Ver mapa
A29: Durango capital | B29: Durango | C29: Lavandería Express | D29: Avenida Real del Mezquital Sin Número, Fraccionamiento Real del Mezquital | F29: Ver mapa
A30: Durango capital | B30: Durango | C30: Lavandería Gemma | D30: Calle Sigma 110, Fraccionamiento Bosques del Valle | F30: Ver mapa
A31: Durango capital | B31: Durango | C31: Lavandería Haiti | D31: Calle Haiti 114, Fraccionamiento Jardines de Durango | F31: Ver mapa
A32: Durango capital | B32: Durango | C32: Lavandería Hipoddromo | D32: Calle Santiago Papasquiaro 501, Colonia Hipódromo | F32: Ver mapa
A33: Durango capital | B33: Durango | C33: Lavandería la Brisa | D33: Cerrada 3ra San Martin 113, Colonia San Juan | F33: Ver mapa
... A73: Durango capital | B73: Durango | C73: Tintorería Max | D73: Boulevard Francisco Villa 1410, Colonia Rio Florido | F73: Ver mapa
A74: Durango capital | B74: Durango | C74: Tintorería Rapida Max | D74: Boulevard Felipe Pescador 1101, Interior 1, Colonia Esperanza | E74: tinto.max1@gmail.com | F74: Ver mapa
A75: Durango capital | B75: Durango | C75: White Tec Lavandería | D75: Calle Mision de Santa Lucia 220 a, Fraccionamiento Tres Misiones | F75: Ver mapa
A76: Gómez Palacio y Lerdo | B76: Gómez Palacio | C76: Acabados Textiles Lavandería Industrial | D76: Prolongacion Valle del Guadiana 672, Sin Nombre, Parque Industrial Carlos a Herrera Araluce | E76: acatex@prodigy.net.com | F76: Ver mapa
A77: Gómez Palacio y Lerdo | B77: Gómez Palacio | C77: Almacen Lavartex Seao | D77: Calzada Carlos Herrera Araluce Sin Número, Ampliacion Santa Rosa | F77: Ver mapa
A78: Gómez Palacio y Lerdo | B78: Gómez Palacio | C78: Hi Clear | D78: Boulevard Isidoro Leal Rodriguez 3388, Colonia los Álamos | E78: hicleartintoreria@outl.com | F78: Ver mapa
A79: Gómez Palacio y Lerdo | B79: Gómez Palacio | C79: La Plancha Servicio de Planchado | D79: Avenida Independencia Sin Número, Colonia Ampliación Bellavista | F79: Ver mapa
...
